Workbook

Sheet SYAHBANDAR15AGUSTUS
A2: NAMA KAPAL | C2: : PULAU MAS 88 | E2: PELABUHAN ASAL | H2: : LOMBOK
A3: GT | C3: : 119 | E3: PELABUHAN TUJUAN | H3: : LABUAN BAJO
A4: JUMLAH ABK | C4: : 8 ORANG | E4: TANGGAL | H4: : 15 AGUSTUS 2026
N5: BLN/TGL/THN
A6: NO. | B6: NAMA | D6: KELAS | E6: F/M | F6: UMUR | H6: NO. PASSPOR | I6: KEBANGSAAN | J6: AGENT/WEB | K6: AREA | L6: PRICE | N6: LAHIR | O6: Hari
A8: 1 | B8: AZMI | D8: CABIN SEA VIEW | E8: F | F8: =DATEDIF(N8,TODAY(),"y") -> 24 | G8: THN | H8: NWC17HPK9 | I8: NEDERLANDEN | J8: AZMI | K8: PEMENANG | L8: 4600000 | N8: 37250 | O8: RABU
A9: 2 | B9: AZMI | D9: CABIN SEA VIEW | E9: F | F9: =DATEDIF(N9,TODAY(),"y") -> 26 | G9: THN | H9: NP2L28H66 | I9: NEDERLANDEN | J9: AZMI | K9: PEMENANG | L9: 4600000 | N9: 36653 | O9: RABU
A10: 3 | B10: AZMI | D10: CABIN SEA VIEW | E10: M | F10: =DATEDIF(N10,TODAY(),"y") -> 26 | G10: THN | H10: PAU272578 | I10: ESPANOLA | J10: AZMI | K10: PEMENANG | L10: 4600000 | N10: 36747 | O10: SELASA
A11: 4 | B11: AZMI | D11: CABIN SEA VIEW | E11: M | F11: =DATEDIF(N11,TODAY(),"y") -> 25 | G11: THN | H11: PAT913888 | I11: ESPANOLA | J11: AZMI | K11: PEMENANG | L11: 4600000 | N11: 36886 | O11: SELASA
A12: 5 | B12: AZMI | D12: CABIN SEA VIEW | E12: M | F12: =DATEDIF(N12,TODAY(),"y") -> 22 | G12: THN | H12: PB1903677 | I12: SLOVENIJA | J12: AZMI | K12: PEMENANG | L12: 4600000 | N12: 37999 | O12: SENIN
A13: 6 | B13: AZMI | D13: CABIN SEA VIEW | E13: F | F13: =DATEDIF(N13,TODAY(),"y") -> 22 | G13: THN | H13: E4487826 | I13: SLOVENIJA | J13: AZMI | K13: PEMENANG | L13: 4600000 | N13: 38022 | O13: RABU
A14: 7 | D14: CABIN SEA VIEW | E14: M | F14: =DATEDIF(N14,TODAY(),"y") -> 23 | G14: THN | H14: C8091557 | I14: INDONESIA | J14: AZMI | K14: KOPANG | L14: 4600000 | N14: 37634 | O14: RABU
A15: 8 | D15: CABIN SEA VIEW | E15: M | F15: =DATEDIF(N15,TODAY(),"y") -> 21 | G15: THN | H15: C84HVN74X | I15: DEUTSCHLAND | J15: AZMI | K15: KOPANG | L15: 4600000 | N15: 38260 | O15: SENIN
A16: 9 | B16: AZMI | D16: CABIN STANDARD | E16: M | F16: =DATEDIF(N16,TODAY(),"y") -> 45 | G16: THN | H16: EM2217146 | I16: NEDERLANDEN | J16: WEB | K16: KOPANG | L16: 4200000 | N16: 29738 | O16: RABU
A17: 10 | B17: AZMI | D17: CABIN STANDARD | E17: F | F17: =DATEDIF(N17,TODAY(),"y") -> 12 | G17: THN | H17: EM3793927 | I17: NEDERLANDEN | J17: WEB | K17: KOPANG | L17: 4200000 | N17: 41522 | O17: RABU
A18: 11 | D18: CABIN STANDARD | E18: F | F18: =DATEDIF(N18,TODAY(),"y") -> 32 | G18: THN | H18: BA985745 | I18: COLOMBIA | J18: AZMI | K18: PEMENANG | L18: 4200000 | N18: 34269 | O18: RABU
A19: 12 | D19: CABIN STANDARD | E19: M | F19: =DATEDIF(N19,TODAY(),"y") -> 47 | G19: THN | H19: BG332521 | I19: COLOMBIA | J19: AZMI | K19: PEMENANG | L19: 4200000 | N19: 28759 | O19: SENIN
A20: 13 | B20: TANISHA UDAY JHAVERY | D20: DOWN DACK | E20: F | F20: =DATEDIF(N20,TODAY(),"y") -> 25 | G20: THN | H20: T6709686 | I20: INDIA | J20: AZMI | K20: PEMENANG | L20: 3800000 | N20: 36894 | O20: RABU
A21: 14 | D21: DOWN DACK | E21: F | F21: 21 | G21: THN | H21: 22AF76354 | I21: FRANCE | J21: AZMI | K21: PEMENANG | L21: 3800000 | N21: 35265 | O21: SENIN
A22: 15 | D22: DOWN DACK | E22: F | F22: =DATEDIF(N22,TODAY(),"y") -> 31 | G22: THN | H22: 26CE41288 | I22: FRANCE | J22: AZMI | K22: PEMENANG | L22: 3800000 | N22: 34712 | O22: SENIN
A23: 16 | D23: DOWN DACK | E23: F | F23: =DATEDIF(N23,TODAY(),"y") -> 39 | G23: THN | H23: 18A153846 | I23: FRANCE | J23: WEB | K23: KOPANG | L23: 3800000 | N23: 31871 | O23: SENIN
A24: 17 | D24: DOWN DACK | E24: M | F24: =DATEDIF(N24,TODAY(),"y") -> 37 | G24: THN | H24: 25HD16890 | I24: FRANCE | J24: WEB | K24: KOPANG | L24: 3800000 | N24: 32491
A25: 18 | D25: DOWN DACK | E25: F | F25: =DATEDIF(N25,TODAY(),"y") -> 34 | G25: THN | H25: 24CF83902 | I25: FRANCE | J25: AZMI | K25: PEMENANG | L25: 3800000 | N25: 33790
A26: 19 | D26: DOWN DACK | E26: M | F26: =DATEDIF(N26,TODAY(),"y") -> 32 | G26: THN | H26: 26AA18263 | I26: FRANCE | J26: AZMI | K26: PEMENANG | L26: 3800000 | N26: 34474
A27: 20 | D27: DOWN DACK | E27: F | F27: 26 | G27: THN | H27: 126789690 | I27: BRITISH CITIZEN | J27: AZMI | K27: PEMENANG | L27: 3800000 | N27: 36544 | O27: RABU
A28: 21 | D28: DOWN DACK
A29: 22 | D29: DOWN DACK
A30: 23 | D30: DOWN DACK
A31: 24 | D31: DOWN DACK
A32: 25 | D32: DOWN DACK
A33: 26 | D33: DOWN DACK
A34: 27 | D34: DOWN DACK
A35: 28 | D35: DOWN DACK
A36: 29 | D36: DOWN DACK
A37: 30 | D37: DOWN DACK | E37: M | F37: 24 | G37: THN | H37: CD188666 | I37: PORTUGUESE | J37: AZMI | K37: PEMENANG | L37: 3800000 | N37: 36251 | O37: RABU
A38: 31 | D38: SHARING CABIN | E38: F | F38: =DATEDIF(N38,TODAY(),"y") -> 24 | G38: THN | H38: 142949050 | I38: BRITISH CITIZEN | J38: AZMI | K38: PEMENANG | L38: 3800000 | N38: 37308 | O38: RABU
A39: 32 | D39: SHARING CABIN | E39: F | F39: =DATEDIF(N39,TODAY(),"y") -> 23 | G39: THN | H39: 120108556 | I39: BRITISH CITIZEN | J39: AZMI | K39: PEMENANG | L39: 3600000 | N39: 37786
A40: 33 | D40: SHARING CABIN | E40: F | F40: =DATEDIF(N40,TODAY(),"y") -> 22 | G40: THN | H40: 130591423 | I40: UNITED KINGDOM | J40: AZMI | K40: PEMENANG | L40: 3600000 | N40: 38014
A41: 34 | D41: SHARING CABIN | E41: F | F41: =DATEDIF(N41,TODAY(),"y") -> 22 | G41: THN | H41: 132499286 | I41: UNITED KINGDOM | J41: AZMI | K41: PEMENANG | L41: 3600000 | N41: 38090
A42: 35 | D42: SHARING CABIN
...

Sheet TAMU15AGUSTUS
A1: PASSANGER LIST
A3: NAMA KAPAL | C3: : PULAU MAS 88 | E3: PELABUHAN ASAL | H3: : LOMBOK
A4: GT | C4: : 119 | E4: PELABUHAN TUJUAN | H4: : LABUAN BAJO
A5: JUMLAH ABK | C5: : 8 ORANG | E5: TANGGAL | H5: : 13 JUNI 2026
M6: FEE | Q6: BLN/TGL/THN
A7: NO. | B7: NAMA | D7: KELAS | E7: F/M | F7: UMUR | H7: NO. PASSPOR | I7: KEBANGSAAN | J7: AGENT/WEB | K7: AREA | L7: PRICE | M7: PRIBADI | N7: AGEN | O7: BERSIH | Q7: LAHIR
A9: 1 | B9: =SYAHBANDAR15AGUSTUS!B12 -> AZMI | D9: CABIN SEA VIEW | E9: =SYAHBANDAR15AGUSTUS!E8 -> F | F9: =DATEDIF(Q9,TODAY(),"y") -> 24 | G9: THN | H9: =SYAHBANDAR15AGUSTUS!H8 -> NWC17HPK9 | I9: =SYAHBANDAR15AGUSTUS!I8 -> NEDERLANDEN | J9: =SYAHBANDAR15AGUSTUS!J8 -> AZMI | K9: =SYAHBANDAR15AGUSTUS!K8 -> PEMENANG | L9: 4600000 | M9: 300000 | N9: 750000 | O9: =L9-M9-N9 -> 3550000 | Q9: =SYAHBANDAR15AGUSTUS!N8 -> 37250 | S9: 700000 | T9: =S9/L9 -> 0.15217391
A10: 2 | B10: =SYAHBANDAR15AGUSTUS!B9 -> AZMI | D10: CABIN SEA VIEW | E10: =SYAHBANDAR15AGUSTUS!E9 -> F | F10: =DATEDIF(Q10,TODAY(),"y") -> 26 | G10: THN | H10: =SYAHBANDAR15AGUSTUS!H9 -> NP2L28H66 | I10: =SYAHBANDAR15AGUSTUS!I9 -> NEDERLANDEN | J10: =SYAHBANDAR15AGUSTUS!J9 -> AZMI | K10: =SYAHBANDAR15AGUSTUS!K9 -> PEMENANG | L10: 4600000 | M10: 300000 | N10: 750000 | O10: =L10-M10-N10 -> 3550000 | Q10: =SYAHBANDAR15AGUSTUS!N9 -> 36653
A11: 3 | B11: =SYAHBANDAR15AGUSTUS!B10 -> AZMI | D11: CABIN SEA VIEW | E11: =SYAHBANDAR15AGUSTUS!E10 -> M | F11: =DATEDIF(Q11,TODAY(),"y") -> 26 | G11: THN | H11: =SYAHBANDAR15AGUSTUS!H10 -> PAU272578 | I11: =SYAHBANDAR15AGUSTUS!I10 -> ESPANOLA | J11: =SYAHBANDAR15AGUSTUS!J10 -> AZMI | K11: =SYAHBANDAR15AGUSTUS!K10 -> PEMENANG | L11: 4600000 | M11: 300000 | N11: 750000 | O11: =L11-M11-N11 -> 3550000 | Q11: =SYAHBANDAR15AGUSTUS!N10 -> 36747
A12: 4 | B12: =SYAHBANDAR15AGUSTUS!B11 -> AZMI | D12: CABIN SEA VIEW | E12: =SYAHBANDAR15AGUSTUS!E11 -> M | F12: =DATEDIF(Q12,TODAY(),"y") -> 25 | G12: THN | H12: =SYAHBANDAR15AGUSTUS!H11 -> PAT913888 | I12: =SYAHBANDAR15AGUSTUS!I11 -> ESPANOLA | J12: =SYAHBANDAR15AGUSTUS!J11 -> AZMI | K12: =SYAHBANDAR15AGUSTUS!K11 -> PEMENANG | L12: 4600000 | M12: 300000 | N12: 750000 | O12: =L12-M12-N12 -> 3550000 | Q12: =SYAHBANDAR15AGUSTUS!N11 -> 36886
A13: 5 | B13: =SYAHBANDAR15AGUSTUS!#REF! -> #REF! | D13: CABIN SEA VIEW | E13: =SYAHBANDAR15AGUSTUS!E12 -> M | F13: =DATEDIF(Q13,TODAY(),"y") -> 22 | G13: THN | H13: =SYAHBANDAR15AGUSTUS!H12 -> PB1903677 | I13: =SYAHBANDAR15AGUSTUS!I12 -> SLOVENIJA | J13: =SYAHBANDAR15AGUSTUS!J12 -> AZMI | K13: =SYAHBANDAR15AGUSTUS!K12 -> PEMENANG | L13: 4600000 | M13: 300000 | N13: 750000 | O13: =L13-M13-N13 -> 3550000 | Q13: =SYAHBANDAR15AGUSTUS!N12 -> 37999
A14: 6 | B14: =SYAHBANDAR15AGUSTUS!B13 -> AZMI | D14: CABIN SEA VIEW | E14: =SYAHBANDAR15AGUSTUS!E13 -> F | F14: =DATEDIF(Q14,TODAY(),"y") -> 22 | G14: THN | H14: =SYAHBANDAR15AGUSTUS!H13 -> E4487826 | I14: =SYAHBANDAR15AGUSTUS!I13 -> SLOVENIJA | J14: =SYAHBANDAR15AGUSTUS!J13 -> AZMI | K14: =SYAHBANDAR15AGUSTUS!K13 -> PEMENANG | L14: 4600000 | M14: 300000 | N14: 750000 | O14: =L14-M14-N14 -> 3550000 | Q14: =SYAHBANDAR15AGUSTUS!N13 -> 38022
A15: 7 | B15: =SYAHBANDAR15AGUSTUS!B14 -> 0 | D15: CABIN SEA VIEW | E15: =SYAHBANDAR15AGUSTUS!E14 -> M | F15: =DATEDIF(Q15,TODAY(),"y") -> 23 | G15: THN | H15: =SYAHBANDAR15AGUSTUS!H14 -> C8091557 | I15: =SYAHBANDAR15AGUSTUS!I14 -> INDONESIA | J15: =SYAHBANDAR15AGUSTUS!J14 -> AZMI | K15: =SYAHBANDAR15AGUSTUS!K14 -> KOPANG | M15: 300000 | N15: 750000 | O15: =L15-M15-N15 -> -1050000 | Q15: =SYAHBANDAR15AGUSTUS!N14 -> 37634
A16: 8 | B16: =SYAHBANDAR15AGUSTUS!B15 -> 0 | D16: CABIN SEA VIEW | E16: =SYAHBANDAR15AGUSTUS!E15 -> M | F16: =DATEDIF(Q16,TODAY(),"y") -> 21 | G16: THN | H16: =SYAHBANDAR15AGUSTUS!H15 -> C84HVN74X | I16: =SYAHBANDAR15AGUSTUS!I15 -> DEUTSCHLAND | J16: =SYAHBANDAR15AGUSTUS!J15 -> AZMI | K16: =SYAHBANDAR15AGUSTUS!K15 -> KOPANG | M16: 300000 | N16: 750000 | O16: =L16-M16-N16 -> -1050000 | Q16: =SYAHBANDAR15AGUSTUS!N15 -> 38260
A17: 9 | B17: =SYAHBANDAR15AGUSTUS!B16 -> AZMI | D17: CABIN STANDARD | E17: =SYAHBANDAR15AGUSTUS!E16 -> M | F17: =DATEDIF(Q17,TODAY(),"y") -> 45 | G17: THN | H17: =SYAHBANDAR15AGUSTUS!H16 -> EM2217146 | I17: =SYAHBANDAR15AGUSTUS!I16 -> NEDERLANDEN | J17: =SYAHBANDAR15AGUSTUS!J16 -> WEB | K17: =SYAHBANDAR15AGUSTUS!K16 -> KOPANG | L17: 4200000 | M17: 300000 | N17: 750000 | O17: =L17-M17-N17 -> 3150000 | Q17: =SYAHBANDAR15AGUSTUS!N16 -> 29738 | S17: 700000 | T17: =S17/L17 -> 0.16666667
A18: 10 | B18: =SYAHBANDAR15AGUSTUS!B17 -> AZMI | D18: CABIN STANDARD | E18: =SYAHBANDAR15AGUSTUS!E17 -> F | F18: =DATEDIF(Q18,TODAY(),"y") -> 12 | G18: THN | H18: =SYAHBANDAR15AGUSTUS!H17 -> EM3793927 | I18: =SYAHBANDAR15AGUSTUS!I17 -> NEDERLANDEN | J18: =SYAHBANDAR15AGUSTUS!J17 -> WEB | K18: =SYAHBANDAR15AGUSTUS!K17 -> KOPANG | L18: 4200000 | M18: 300000 | N18: 750000 | O18: =L18-M18-N18 -> 3150000 | Q18: =SYAHBANDAR15AGUSTUS!N17 -> 41522
A19: 11 | B19: =SYAHBANDAR15AGUSTUS!B18 -> 0 | D19: CABIN STANDARD | E19: =SYAHBANDAR15AGUSTUS!E18 -> F | F19: =DATEDIF(Q19,TODAY(),"y") -> 32 | G19: THN | H19: =SYAHBANDAR15AGUSTUS!H18 -> BA985745 | I19: =SYAHBANDAR15AGUSTUS!I18 -> COLOMBIA | J19: =SYAHBANDAR15AGUSTUS!J18 -> AZMI | K19: =SYAHBANDAR15AGUSTUS!K18 -> PEMENANG | L19: 4200000 | M19: 300000 | N19: 750000 | O19: =L19-M19-N19 -> 3150000 | Q19: =SYAHBANDAR15AGUSTUS!N18 -> 34269
A20: 12 | B20: =SYAHBANDAR15AGUSTUS!B19 -> 0 | D20: CABIN STANDARD | E20: =SYAHBANDAR15AGUSTUS!E19 -> M | F20: =DATEDIF(Q20,TODAY(),"y") -> 47 | G20: THN | H20: =SYAHBANDAR15AGUSTUS!H19 -> BG332521 | I20: =SYAHBANDAR15AGUSTUS!I19 -> COLOMBIA | J20: =SYAHBANDAR15AGUSTUS!J19 -> AZMI | K20: =SYAHBANDAR15AGUSTUS!K19 -> PEMENANG | L20: 4200000 | M20: 300000 | N20: 750000 | O20: =L20-M20-N20 -> 3150000 | Q20: =SYAHBANDAR15AGUSTUS!N19 -> 28759
A21: 13 | B21: =SYAHBANDAR15AGUSTUS!B20 -> TANISHA UDAY JHAVERY | D21: DOWN DECK | E21: =SYAHBANDAR15AGUSTUS!E20 -> F | F21: =DATEDIF(Q21,TODAY(),"y") -> 30 | G21: THN | H21: =SYAHBANDAR15AGUSTUS!H20 -> T6709686 | I21: =SYAHBANDAR15AGUSTUS!I20 -> INDIA | J21: =SYAHBANDAR15AGUSTUS!J20 -> AZMI | K21: =SYAHBANDAR15AGUSTUS!K20 -> PEMENANG | L21: 3800000 | M21: 300000 | N21: 750000 | O21: =L21-M21-N21 -> 2750000 | Q21: 35147 | S21: 700000 | T21: =S21/L21 -> 0.18421053
A22: 14 | B22: =SYAHBANDAR15AGUSTUS!B21 -> 0 | D22: DOWN DECK | E22: =SYAHBANDAR15AGUSTUS!E21 -> F | F22: =DATEDIF(Q22,TODAY(),"y") -> 25 | G22: THN | H22: =SYAHBANDAR15AGUSTUS!H21 -> 22AF76354 | I22: =SYAHBANDAR15AGUSTUS!I21 -> FRANCE | J22: =SYAHBANDAR15AGUSTUS!J21 -> AZMI | K22: =SYAHBANDAR15AGUSTUS!K21 -> PEMENANG | L22: 3800000 | M22: 300000 | N22: 750000 | O22: =L22-M22-N22 -> 2750000 | Q22: 36967
A23: 15 | B23: =SYAHBANDAR15AGUSTUS!B22 -> 0 | D23: DOWN DECK | E23: =SYAHBANDAR15AGUSTUS!E22 -> F | F23: =DATEDIF(Q23,TODAY(),"y") -> 31 | G23: THN | H23: =SYAHBANDAR15AGUSTUS!H22 -> 26CE41288 | I23: =SYAHBANDAR15AGUSTUS!I22 -> FRANCE | J23: =SYAHBANDAR15AGUSTUS!J22 -> AZMI | K23: =SYAHBANDAR15AGUSTUS!K22 -> PEMENANG | M23: 300000 | N23: 750000 | O23: =L23-M23-N23 -> -1050000 | Q23: =SYAHBANDAR15AGUSTUS!N22 -> 34712
A24: 16 | B24: =SYAHBANDAR15AGUSTUS!B23 -> 0 | D24: DOWN DECK | E24: =SYAHBANDAR15AGUSTUS!E23 -> F | F24: =DATEDIF(Q24,TODAY(),"y") -> 39 | G24: THN | H24: =SYAHBANDAR15AGUSTUS!H23 -> 18A153846 | I24: =SYAHBANDAR15AGUSTUS!I23 -> FRANCE | J24: =SYAHBANDAR15AGUSTUS!J23 -> WEB | K24: =SYAHBANDAR15AGUSTUS!K23 -> KOPANG | M24: 300000 | N24: 750000 | O24: =L24-M24-N24 -> -1050000 | Q24: =SYAHBANDAR15AGUSTUS!N23 -> 31871
A25: 17 | B25: =SYAHBANDAR15AGUSTUS!B24 -> 0 | D25: SHARING CABIN | E25: =SYAHBANDAR15AGUSTUS!E24 -> M | F25: =DATEDIF(Q25,TODAY(),"y") -> 37 | G25: THN | H25: =SYAHBANDAR15AGUSTUS!H24 -> 25HD16890 | I25: =SYAHBANDAR15AGUSTUS!I24 -> FRANCE | J25: =SYAHBANDAR15AGUSTUS!J24 -> WEB | K25: =SYAHBANDAR15AGUSTUS!K24 -> KOPANG | L25: 3600000 | M25: 300000 | N25: 750000 | O25: =L25-M25-N25 -> 2550000 | Q25: =SYAHBANDAR15AGUSTUS!N24 -> 32491 | S25: 700000 | T25: =S25/L25 -> 0.19444444
A26: 18 | B26: =SYAHBANDAR15AGUSTUS!B25 -> 0 | D26: SHARING CABIN | E26: =SYAHBANDAR15AGUSTUS!E25 -> F | F26: =DATEDIF(Q26,TODAY(),"y") -> 34 | G26: THN | H26: =SYAHBANDAR15AGUSTUS!H25 -> 24CF83902 | I26: =SYAHBANDAR15AGUSTUS!I25 -> FRANCE | J26: =SYAHBANDAR15AGUSTUS!J25 -> AZMI | K26: =SYAHBANDAR15AGUSTUS!K25 -> PEMENANG | L26: 3600000 | M26: 300000 | N26: 750000 | O26: =L26-M26-N26 -> 2550000 | Q26: =SYAHBANDAR15AGUSTUS!N25 -> 33790
A27: 19 | B27: =SYAHBANDAR15AGUSTUS!B26 -> 0 | D27: SHARING CABIN | E27: =SYAHBANDAR15AGUSTUS!E26 -> M | F27: =DATEDIF(Q27,TODAY(),"y") -> 32 | G27: THN | H27: =SYAHBANDAR15AGUSTUS!H26 -> 26AA18263 | I27: =SYAHBANDAR15AGUSTUS!I26 -> FRANCE | J27: =SYAHBANDAR15AGUSTUS!J26 -> AZMI | K27: =SYAHBANDAR15AGUSTUS!K26 -> PEMENANG | L27: 3600000 | M27: 300000 | N27: 750000 | O27: =L27-M27-N27 -> 2550000 | Q27: =SYAHBANDAR15AGUSTUS!N26 -> 34474
A28: 20 | B28: =SYAHBANDAR15AGUSTUS!B27 -> 0 | D28: SHARING CABIN | E28: =SYAHBANDAR15AGUSTUS!E27 -> F | F28: =DATEDIF(Q28,TODAY(),"y") -> 26 | G28: THN | H28: =SYAHBANDAR15AGUSTUS!H27 -> 126789690 | I28: =SYAHBANDAR15AGUSTUS!I27 -> BRITISH CITIZEN | J28: =SYAHBANDAR15AGUSTUS!J27 -> AZMI | K28: =SYAHBANDAR15AGUSTUS!K27 -> PEMENANG | L28: 3600000 | M28: 300000 | N28: 750000 | O28: =L28-M28-N28 -> 2550000 | Q28: =SYAHBANDAR15AGUSTUS!N27 -> 36544
A29: 21 | B29: =SYAHBANDAR15AGUSTUS!B37 -> 0 | D29: SHARING CABIN | E29: =SYAHBANDAR15AGUSTUS!E37 -> M | F29: =DATEDIF(Q29,TODAY(),"y") -> 27 | G29: THN | H29: =SYAHBANDAR15AGUSTUS!H37 -> CD188666 | I29: =SYAHBANDAR15AGUSTUS!I37 -> PORTUGUESE | J29: =SYAHBANDAR15AGUSTUS!J37 -> AZMI | K29: =SYAHBANDAR15AGUSTUS!K37 -> PEMENANG | L29: 3600000 | M29: 300000 | N29: 750000 | O29: =L29-M29-N29 -> 2550000 | Q29: =SYAHBANDAR15AGUSTUS!N37 -> 36251
A30: 22 | B30: =SYAHBANDAR15AGUSTUS!B38 -> 0 | D30: SHARING CABIN | E30: =SYAHBANDAR15AGUSTUS!E38 -> F | F30: =DATEDIF(Q30,TODAY(),"y") -> 24 | G30: THN | H30: =SYAHBANDAR15AGUSTUS!H38 -> 142949050 | I30: =SYAHBANDAR15AGUSTUS!I38 -> BRITISH CITIZEN | J30: =SYAHBANDAR15AGUSTUS!J38 -> AZMI | K30: =SYAHBANDAR15AGUSTUS!K38 -> PEMENANG | L30: 3600000 | M30: 300000 | N30: 750000 | O30: =L30-M30-N30 -> 2550000 | Q30: =SYAHBANDAR15AGUSTUS!N38 -> 37308
A31: 23 | B31: =SYAHBANDAR15AGUSTUS!B39 -> 0 | D31: SHARING CABIN | E31: =SYAHBANDAR15AGUSTUS!E39 -> F | F31: =DATEDIF(Q31,TODAY(),"y") -> 23 | G31: THN | H31: =SYAHBANDAR15AGUSTUS!H39 -> 120108556 | I31: =SYAHBANDAR15AGUSTUS!I39 -> BRITISH CITIZEN | J31: =SYAHBANDAR15AGUSTUS!J39 -> AZMI | K31: =SYAHBANDAR15AGUSTUS!K39 -> PEMENANG | L31: 3600000 | M31: 300000 | N31: 750000 | O31: =L31-M31-N31 -> 2550000 | Q31: =SYAHBANDAR15AGUSTUS!N39 -> 37786
A32: 24 | B32: =SYAHBANDAR15AGUSTUS!B40 -> 0 | D32: SHARING CABIN | E32: =SYAHBANDAR15AGUSTUS!E62 -> F | F32: =DATEDIF(Q32,TODAY(),"y") -> 22 | G32: THN | H32: =SYAHBANDAR15AGUSTUS!H40 -> 130591423 | I32: =SYAHBANDAR15AGUSTUS!I40 -> UNITED KINGDOM | J32: =SYAHBANDAR15AGUSTUS!J40 -> AZMI | K32: =SYAHBANDAR15AGUSTUS!K40 -> PEMENANG | L32: 3600000 | M32: 300000 | N32: 750000 | O32: =L32-M32-N32 -> 2550000 | Q32: =SYAHBANDAR15AGUSTUS!N40 -> 38014
A33: 25 | B33: =SYAHBANDAR15AGUSTUS!B41 -> 0 | D33: SHARING CABIN | E33: F | F33: =DATEDIF(Q33,TODAY(),"y") -> 22 | G33: THN | H33: =SYAHBANDAR15AGUSTUS!H41 -> 132499286 | I33: =SYAHBANDAR15AGUSTUS!I41 -> UNITED KINGDOM | J33: =SYAHBANDAR15AGUSTUS!J41 -> AZMI | K33: =SYAHBANDAR15AGUSTUS!K41 -> PEMENANG | L33: 3600000 | M33: 300000 | N33: 750000 | O33: =L33-M33-N33 -> 2550000 | Q33: =SYAHBANDAR15AGUSTUS!N41 -> 38090
A34: 26 | B34: =SYAHBANDAR15AGUSTUS!B62 -> 0 | D34: SHARING CABIN | E34: =SYAHBANDAR15AGUSTUS!E62 -> F | F34: =DATEDIF(Q34,TODAY(),"y") -> 23 | G34: THN | H34: =SYAHBANDAR15AGUSTUS!H62 -> 25AH40022 | I34: =SYAHBANDAR15AGUSTUS!I62 -> FRANCE | J34: =SYAHBANDAR15AGUSTUS!J62 -> AZMI | K34: =SYAHBANDAR15AGUSTUS!K62 -> PEMENANG | L34: 3600000 | M34: 300000 | N34: 750000 | O34: =L34-M34-N34 -> 2550000 | Q34: =SYAHBANDAR15AGUSTUS!N62 -> 37821
K36: TOTAL | L36: =SUM(L9:L34) -> 88000000 | M36: =SUM(M9:M34) -> 7800000 | N36: =SUM(N9:N34) -> 19500000 | O36: =SUM(O9:O34) -> 60700000 | S36: =L36*0.17 -> 14960000
